Workbook

Sheet Churn_part
A1: ID_Client | B1: Province_Client | C1: Anciennete_Mois | D1: Type_Forfait | E1: Types client | F1: Duree_Cumulee_Panne_Min | G1: Facture_Mensuelle | H1: Plaintes_Service_Client | I1: Remise Client | J1: Pertes financieres
A2: CLI-01147 | B2: Ituri | C2: 29 | D2: Premium 5G 150Go | E2: =IF(Churn_part[[#This Row],[Type_Forfait]]="Pro Monde", "B2B", "B2C") -> B2C | F2: 214 | G2: 74.7 | H2: 3 | I2: =IF(Churn_part[[#This Row],[Types client]]="B2B",10%, IF(AND(Churn_part[[#This Row],[Duree_Cumulee_Panne_Min]]>720,Churn_part[[#This Row],[Anciennete_Mois]]>60),70%,IF(OR(AND(Churn_part[[#This Row],[Duree_Cumulee_Panne_Min]]>=240,Churn_part[[#This Row],[Anciennete_Mois]]<=720),AND(Churn_part[[#This Row],[Anciennete_Mois]]<60,Churn_part[[#This Row],[Type_Forfait]]="Premium 5G")),45%,0%))) -> 0 | J2: =Churn_part[[#This Row],[Facture_Mensuelle]]*Churn_part[[#This Row],[Remise Client]] -> 0
A3: CLI-00894 | B3: Tshuapa | C3: 63 | D3: Pro Monde | E3: =IF(Churn_part[[#This Row],[Type_Forfait]]="Pro Monde", "B2B", "B2C") -> B2B | F3: 205 | G3: 89.19 | H3: 0 | I3: =IF(Churn_part[[#This Row],[Types client]]="B2B",10%, IF(AND(Churn_part[[#This Row],[Duree_Cumulee_Panne_Min]]>720,Churn_part[[#This Row],[Anciennete_Mois]]>60),70%,IF(OR(AND(Churn_part[[#This Row],[Duree_Cumulee_Panne_Min]]>=240,Churn_part[[#This Row],[Anciennete_Mois]]<=720),AND(Churn_part[[#This Row],[Anciennete_Mois]]<60,Churn_part[[#This Row],[Type_Forfait]]="Premium 5G")),45%,0%))) -> 0.1 | J3: =Churn_part[[#This Row],[Facture_Mensuelle]]*Churn_part[[#This Row],[Remise Client]] -> 8.919
A4: CLI-00865 | B4: Mongala | C4: 34 | D4: Pro Monde | E4: =IF(Churn_part[[#This Row],[Type_Forfait]]="Pro Monde", "B2B", "B2C") -> B2B | F4: 453 | G4: 56.84 | H4: 0 | I4: =IF(Churn_part[[#This Row],[Types client]]="B2B",10%, IF(AND(Churn_part[[#This Row],[Duree_Cumulee_Panne_Min]]>720,Churn_part[[#This Row],[Anciennete_Mois]]>60),70%,IF(OR(AND(Churn_part[[#This Row],[Duree_Cumulee_Panne_Min]]>=240,Churn_part[[#This Row],[Anciennete_Mois]]<=720),AND(Churn_part[[#This Row],[Anciennete_Mois]]<60,Churn_part[[#This Row],[Type_Forfait]]="Premium 5G")),45%,0%))) -> 0.1 | J4: =Churn_part[[#This Row],[Facture_Mensuelle]]*Churn_part[[#This Row],[Remise Client]] -> 5.684
A5: CLI-01325 | B5: Haut-Lomami | C5: 44 | D5: Bloqué 5Go | E5: =IF(Churn_part[[#This Row],[Type_Forfait]]="Pro Monde", "B2B", "B2C") -> B2C | F5: 348 | G5: 58.67 | H5: 0 | I5: =IF(Churn_part[[#This Row],[Types client]]="B2B",10%, IF(AND(Churn_part[[#This Row],[Duree_Cumulee_Panne_Min]]>720,Churn_part[[#This Row],[Anciennete_Mois]]>60),70%,IF(OR(AND(Churn_part[[#This Row],[Duree_Cumulee_Panne_Min]]>=240,Churn_part[[#This Row],[Anciennete_Mois]]<=720),AND(Churn_part[[#This Row],[Anciennete_Mois]]<60,Churn_part[[#This Row],[Type_Forfait]]="Premium 5G")),45%,0%))) -> 0.45 | J5: =Churn_part[[#This Row],[Facture_Mensuelle]]*Churn_part[[#This Row],[Remise Client]] -> 26.4015
A6: CLI-01855 | B6: Sud-Kivu | C6: 101 | D6: Illimité 50Go | E6: =IF(Churn_part[[#This Row],[Type_Forfait]]="Pro Monde", "B2B", "B2C") -> B2C | F6: 358 | G6: 29.24 | H6: 3 | I6: =IF(Churn_part[[#This Row],[Types client]]="B2B",10%, IF(AND(Churn_part[[#This Row],[Duree_Cumulee_Panne_Min]]>720,Churn_part[[#This Row],[Anciennete_Mois]]>60),70%,IF(OR(AND(Churn_part[[#This Row],[Duree_Cumulee_Panne_Min]]>=240,Churn_part[[#This Row],[Anciennete_Mois]]<=720),AND(Churn_part[[#This Row],[Anciennete_Mois]]<60,Churn_part[[#This Row],[Type_Forfait]]="Premium 5G")),45%,0%))) -> 0.45 | J6: =Churn_part[[#This Row],[Facture_Mensuelle]]*Churn_part[[#This Row],[Remise Client]] -> 13.158
A7: CLI-00076 | B7: Haut-Katanga | C7: 46 | D7: Premium 5G 150Go | E7: =IF(Churn_part[[#This Row],[Type_Forfait]]="Pro Monde", "B2B", "B2C") -> B2C | F7: 283 | G7: 56.05 | H7: 1 | I7: =IF(Churn_part[[#This Row],[Types client]]="B2B",10%, IF(AND(Churn_part[[#This Row],[Duree_Cumulee_Panne_Min]]>720,Churn_part[[#This Row],[Anciennete_Mois]]>60),70%,IF(OR(AND(Churn_part[[#This Row],[Duree_Cumulee_Panne_Min]]>=240,Churn_part[[#This Row],[Anciennete_Mois]]<=720),AND(Churn_part[[#This Row],[Anciennete_Mois]]<60,Churn_part[[#This Row],[Type_Forfait]]="Premium 5G")),45%,0%))) -> 0.45 | J7: =Churn_part[[#This Row],[Facture_Mensuelle]]*Churn_part[[#This Row],[Remise Client]] -> 25.2225
A8: CLI-00414 | B8: Bas-Uele | C8: 99 | D8: Premium 5G 150Go | E8: =IF(Churn_part[[#This Row],[Type_Forfait]]="Pro Monde", "B2B", "B2C") -> B2C | F8: 447 | G8: 38.1 | H8: 3 | I8: =IF(Churn_part[[#This Row],[Types client]]="B2B",10%, IF(AND(Churn_part[[#This Row],[Duree_Cumulee_Panne_Min]]>720,Churn_part[[#This Row],[Anciennete_Mois]]>60),70%,IF(OR(AND(Churn_part[[#This Row],[Duree_Cumulee_Panne_Min]]>=240,Churn_part[[#This Row],[Anciennete_Mois]]<=720),AND(Churn_part[[#This Row],[Anciennete_Mois]]<60,Churn_part[[#This Row],[Type_Forfait]]="Premium 5G")),45%,0%))) -> 0.45 | J8: =Churn_part[[#This Row],[Facture_Mensuelle]]*Churn_part[[#This Row],[Remise Client]] -> 17.145
A9: CLI-00327 | B9: Haut-Katanga | C9: 6 | D9: Illimité 50Go | E9: =IF(Churn_part[[#This Row],[Type_Forfait]]="Pro Monde", "B2B", "B2C") -> B2C | F9: 155 | G9: 40.66 | H9: 1 | I9: =IF(Churn_part[[#This Row],[Types client]]="B2B",10%, IF(AND(Churn_part[[#This Row],[Duree_Cumulee_Panne_Min]]>720,Churn_part[[#This Row],[Anciennete_Mois]]>60),70%,IF(OR(AND(Churn_part[[#This Row],[Duree_Cumulee_Panne_Min]]>=240,Churn_part[[#This Row],[Anciennete_Mois]]<=720),AND(Churn_part[[#This Row],[Anciennete_Mois]]<60,Churn_part[[#This Row],[Type_Forfait]]="Premium 5G")),45%,0%))) -> 0 | J9: =Churn_part[[#This Row],[Facture_Mensuelle]]*Churn_part[[#This Row],[Remise Client]] -> 0
A10: CLI-00559 | B10: Kasai | C10: 99 | D10: Bloqué 5Go | E10: =IF(Churn_part[[#This Row],[Type_Forfait]]="Pro Monde", "B2B", "B2C") -> B2C | F10: 369 | G10: 67.21 | H10: 3 | I10: =IF(Churn_part[[#This Row],[Types client]]="B2B",10%, IF(AND(Churn_part[[#This Row],[Duree_Cumulee_Panne_Min]]>720,Churn_part[[#This Row],[Anciennete_Mois]]>60),70%,IF(OR(AND(Churn_part[[#This Row],[Duree_Cumulee_Panne_Min]]>=240,Churn_part[[#This Row],[Anciennete_Mois]]<=720),AND(Churn_part[[#This Row],[Anciennete_Mois]]<60,Churn_part[[#This Row],[Type_Forfait]]="Premium 5G")),45%,0%))) -> 0.45 | J10: =Churn_part[[#This Row],[Facture_Mensuelle]]*Churn_part[[#This Row],[Remise Client]] -> 30.2445
A11: CLI-00280 | B11: Sud-Ubangi | C11: 113 | D11: Illimité 50Go | E11: =IF(Churn_part[[#This Row],[Type_Forfait]]="Pro Monde", "B2B", "B2C") -> B2C | F11: 380 | G11: 12.11 | H11: 0 | I11: =IF(Churn_part[[#This Row],[Types client]]="B2B",10%, IF(AND(Churn_part[[#This Row],[Duree_Cumulee_Panne_Min]]>720,Churn_part[[#This Row],[Anciennete_Mois]]>60),70%,IF(OR(AND(Churn_part[[#This Row],[Duree_Cumulee_Panne_Min]]>=240,Churn_part[[#This Row],[Anciennete_Mois]]<=720),AND(Churn_part[[#This Row],[Anciennete_Mois]]<60,Churn_part[[#This Row],[Type_Forfait]]="Premium 5G")),45%,0%))) -> 0.45 | J11: =Churn_part[[#This Row],[Facture_Mensuelle]]*Churn_part[[#This Row],[Remise Client]] -> 5.4495
A12: CLI-00060 | B12: Kasai-Central | C12: 72 | D12: Pro Monde | E12: =IF(Churn_part[[#This Row],[Type_Forfait]]="Pro Monde", "B2B", "B2C") -> B2B | F12: 160 | G12: 90.13 | H12: 2 | I12: =IF(Churn_part[[#This Row],[Types client]]="B2B",10%, IF(AND(Churn_part[[#This Row],[Duree_Cumulee_Panne_Min]]>720,Churn_part[[#This Row],[Anciennete_Mois]]>60),70%,IF(OR(AND(Churn_part[[#This Row],[Duree_Cumulee_Panne_Min]]>=240,Churn_part[[#This Row],[Anciennete_Mois]]<=720),AND(Churn_part[[#This Row],[Anciennete_Mois]]<60,Churn_part[[#This Row],[Type_Forfait]]="Premium 5G")),45%,0%))) -> 0.1 | J12: =Churn_part[[#This Row],[Facture_Mensuelle]]*Churn_part[[#This Row],[Remise Client]] -> 9.013
A13: CLI-00530 | B13: Sankuru | C13: 35 | D13: Pro Monde | E13: =IF(Churn_part[[#This Row],[Type_Forfait]]="Pro Monde", "B2B", "B2C") -> B2B | F13: 465 | G13: 58.59 | H13: 5 | I13: =IF(Churn_part[[#This Row],[Types client]]="B2B",10%, IF(AND(Churn_part[[#This Row],[Duree_Cumulee_Panne_Min]]>720,Churn_part[[#This Row],[Anciennete_Mois]]>60),70%,IF(OR(AND(Churn_part[[#This Row],[Duree_Cumulee_Panne_Min]]>=240,Churn_part[[#This Row],[Anciennete_Mois]]<=720),AND(Churn_part[[#This Row],[Anciennete_Mois]]<60,Churn_part[[#This Row],[Type_Forfait]]="Premium 5G")),45%,0%))) -> 0.1 | J13: =Churn_part[[#This Row],[Facture_Mensuelle]]*Churn_part[[#This Row],[Remise Client]] -> 5.859
... A749: CLI-00800 | B749: Nord-Kivu | C749: 4 | D749: Bloqué 5Go | E749: =IF(Churn_part[[#This Row],[Type_Forfait]]="Pro Monde", "B2B", "B2C") -> B2C | F749: 21 | G749: 45.8 | H749: 1 | I749: =IF(Churn_part[[#This Row],[Types client]]="B2B",10%, IF(AND(Churn_part[[#This Row],[Duree_Cumulee_Panne_Min]]>720,Churn_part[[#This Row],[Anciennete_Mois]]>60),70%,IF(OR(AND(Churn_part[[#This Row],[Duree_Cumulee_Panne_Min]]>=240,Churn_part[[#This Row],[Anciennete_Mois]]<=720),AND(Churn_part[[#This Row],[Anciennete_Mois]]<60,Churn_part[[#This Row],[Type_Forfait]]="Premium 5G")),45%,0%))) -> 0 | J749: =Churn_part[[#This Row],[Facture_Mensuelle]]*Churn_part[[#This Row],[Remise Client]] -> 0

Sheet TCD
A1: Statut_Resolution | B1: All
A3: Somme de Duree_Panne_Min | B3: Étiquettes de colonnes
A4: Étiquettes de lignes | B4: 3G | C4: 4G | D4: 5G | E4: Total général
A5: Nord-Kivu | B5: 683 | C5: 327 | D5: 916 | E5: 1926
A6: Kongo-Central | B6: 36 | C6: 457 | D6: 1310 | E6: 1803
A7: Haut-Katanga | B7: 411 | C7: 474 | D7: 669 | E7: 1554
A8: Tanganyika | B8: 341 | C8: 535 | D8: 657 | E8: 1533
A9: Nord-Ubangi | B9: 275 | C9: 772 | D9: 398 | E9: 1445
A10: Sud-Ubangi | B10: 380 | C10: 357 | D10: 612 | E10: 1349
A11: Bas-Uele | B11: 610 | C11: 279 | D11: 453 | E11: 1342
A12: Sud-Kivu | B12: 766 | C12: 120 | D12: 432 | E12: 1318
A13: Tshopo | B13: 535 | C13: 171 | D13: 538 | E13: 1244
A14: Lualaba | B14: 354 | C14: 526 | D14: 264 | E14: 1144
A15: Lomami | B15: 490 | C15: 334 | D15: 266 | E15: 1090
A16: Mongala | B16: 170 | C16: 313 | D16: 591 | E16: 1074
... A19: Kinshasa | B19: 377 | C19: 174 | D19: 455 | E19: 1006
A20: Maniema | C20: 633 | D20: 355 | E20: 988
A21: Equateur | B21: 268 | C21: 118 | D21: 538 | E21: 924
A22: Ituri | B22: 277 | C22: 204 | D22: 426 | E22: 907
A23: Kwilu | B23: 494 | C23: 274 | D23: 110 | E23: 878
A24: Kasai | B24: 116 | C24: 308 | D24: 433 | E24: 857
A25: Kasai-Central | B25: 125 | C25: 488 | D25: 87 | E25: 700
A26: Kwango | C26: 453 | D26: 168 | E26: 621
A27: Kasai-Oriental | B27: 152 | C27: 119 | D27: 298 | E27: 569
A28: Tshuapa | B28: 147 | C28: 75 | D28: 208 | E28: 430
A29: Mai-Ndombe | B29: 98 | C29: 177 | D29: 89 | E29: 364
A30: Sankuru | B30: 34 | C30: 72 | D30: 156 | E30: 262
A31: 0 | B31: 68 | E31: 68
A32: Total général | B32: 7504 | C32: 8683 | D32: 11226 | E32: 27413

Sheet logs_ reseaux
A1: Source.Name | B1: Date_Heure_Panne | C1: Cell_ID | D1: Duree_Panne_Min | E1: Statut_Resolution | F1: Province_RDC | G1: Province_Corrigée | H1: Latitute | I1: Longitude | J1: Technologie | K1: Verification_Province
A2: Logs_Reseau_Part_01.xlsx | B2: 45203.033 | C2: ; | D2: 73 | E2: Résolu | F2: Tanganyika | G2: =IFERROR(VLOOKUP(C2,'Registre maintenance'!B:F,2,FALSE),"Non trouvé") -> Non trouvé | H2: =IFERROR(VLOOKUP(C2,'Registre maintenance'!B:F,3,FALSE),"Non trouvé") -> Non trouvé | I2: =IFERROR(VLOOKUP(C2,'Registre maintenance'!B:F,4,FALSE),"Non trouvé") -> Non trouvé | J2: =IFERROR(VLOOKUP(C2,'Registre maintenance'!B:F,5,FALSE),"Non trouvé") -> Non trouvé | K2: =IF(F2=G2,"OK","Mismatch") -> Mismatch
A3: Logs_Reseau_Part_07.xlsx | B3: 45228.792 | C3: ANT-0465 | D3: 63 | E3: Résolu | F3: Tanganyika | G3: =IFERROR(VLOOKUP(C3,'Registre maintenance'!B:F,2,FALSE),"Non trouvé") -> Tanganyika | H3: =IFERROR(VLOOKUP(C3,'Registre maintenance'!B:F,3,FALSE),"Non trouvé") -> -11.144149 | I3: =IFERROR(VLOOKUP(C3,'Registre maintenance'!B:F,4,FALSE),"Non trouvé") -> 27.244659 | J3: =IFERROR(VLOOKUP(C3,'Registre maintenance'!B:F,5,FALSE),"Non trouvé") -> 4G | K3: =IF(F3=G3,"OK","Mismatch") -> OK
A4: Logs_Reseau_Part_01.xlsx | B4: 45208.301 | C4: ANT-0004 | D4: 38 | E4: Résolu | F4: =F3 -> Tanganyika | G4: =IFERROR(VLOOKUP(C4,'Registre maintenance'!B:F,2,FALSE),"Non trouvé") -> Non trouvé | H4: =IFERROR(VLOOKUP(C4,'Registre maintenance'!B:F,3,FALSE),"Non trouvé") -> Non trouvé | I4: =IFERROR(VLOOKUP(C4,'Registre maintenance'!B:F,4,FALSE),"Non trouvé") -> Non trouvé | J4: =IFERROR(VLOOKUP(C4,'Registre maintenance'!B:F,5,FALSE),"Non trouvé") -> Non trouvé | K4: =IF(F4=G4,"OK","Mismatch") -> Mismatch
A5: Logs_Reseau_Part_02.xlsx | B5: 45226.003 | C5: ANT-0004 | D5: 111 | E5: Résolu | F5: =F4 -> Tanganyika | G5: =IFERROR(VLOOKUP(C5,'Registre maintenance'!B:F,2,FALSE),"Non trouvé") -> Non trouvé | H5: =IFERROR(VLOOKUP(C5,'Registre maintenance'!B:F,3,FALSE),"Non trouvé") -> Non trouvé | I5: =IFERROR(VLOOKUP(C5,'Registre maintenance'!B:F,4,FALSE),"Non trouvé") -> Non trouvé | J5: =IFERROR(VLOOKUP(C5,'Registre maintenance'!B:F,5,FALSE),"Non trouvé") -> Non trouvé | K5: =IF(F5=G5,"OK","Mismatch") -> Mismatch
A6: Logs_Reseau_Part_01.xlsx | B6: 45212.14 | C6: ANT-0862 | D6: 19 | E6: Non Résolu | F6: Tanganyika | G6: =IFERROR(VLOOKUP(C6,'Registre maintenance'!B:F,2,FALSE),"Non trouvé") -> Tanganyika | H6: =IFERROR(VLOOKUP(C6,'Registre maintenance'!B:F,3,FALSE),"Non trouvé") -> -9.470862 | I6: =IFERROR(VLOOKUP(C6,'Registre maintenance'!B:F,4,FALSE),"Non trouvé") -> 29.234388 | J6: =IFERROR(VLOOKUP(C6,'Registre maintenance'!B:F,5,FALSE),"Non trouvé") -> 3G | K6: =IF(F6=G6,"OK","Mismatch") -> OK
A7: Logs_Reseau_Part_01.xlsx | B7: 45204.963 | C7: ANT-0977 | D7: 100 | E7: Non Résolu | F7: =F6 -> Tanganyika | G7: =IFERROR(VLOOKUP(C7,'Registre maintenance'!B:F,2,FALSE),"Non trouvé") -> Non trouvé | H7: =IFERROR(VLOOKUP(C7,'Registre maintenance'!B:F,3,FALSE),"Non trouvé") -> Non trouvé | I7: =IFERROR(VLOOKUP(C7,'Registre maintenance'!B:F,4,FALSE),"Non trouvé") -> Non trouvé | J7: =IFERROR(VLOOKUP(C7,'Registre maintenance'!B:F,5,FALSE),"Non trouvé") -> Non trouvé | K7: =IF(F7=G7,"OK","Mismatch") -> Mismatch
A8: Logs_Reseau_Part_01.xlsx | B8: 45224.378 | C8: ANT-0977 | D8: 53 | E8: En Cours | F8: =F7 -> Tanganyika | G8: =IFERROR(VLOOKUP(C8,'Registre maintenance'!B:F,2,FALSE),"Non trouvé") -> Non trouvé | H8: =IFERROR(VLOOKUP(C8,'Registre maintenance'!B:F,3,FALSE),"Non trouvé") -> Non trouvé | I8: =IFERROR(VLOOKUP(C8,'Registre maintenance'!B:F,4,FALSE),"Non trouvé") -> Non trouvé | J8: =IFERROR(VLOOKUP(C8,'Registre maintenance'!B:F,5,FALSE),"Non trouvé") -> Non trouvé | K8: =IF(F8=G8,"OK","Mismatch") -> Mismatch
A9: Logs_Reseau_Part_01.xlsx | B9: 45221.998 | C9: ANT-0740 | D9: 79 | E9: En Cours | F9: =F8 -> Tanganyika | G9: =IFERROR(VLOOKUP(C9,'Registre maintenance'!B:F,2,FALSE),"Non trouvé") -> Non trouvé | H9: =IFERROR(VLOOKUP(C9,'Registre maintenance'!B:F,3,FALSE),"Non trouvé") -> Non trouvé | I9: =IFERROR(VLOOKUP(C9,'Registre maintenance'!B:F,4,FALSE),"Non trouvé") -> Non trouvé | J9: =IFERROR(VLOOKUP(C9,'Registre maintenance'!B:F,5,FALSE),"Non trouvé") -> Non trouvé | K9: =IF(F9=G9,"OK","Mismatch") -> Mismatch
A10: Logs_Reseau_Part_03.xlsx | B10: 45210.568 | C10: ANT-0913 | D10: 96 | E10: Résolu | F10: Kinshasa | G10: =IFERROR(VLOOKUP(C10,'Registre maintenance'!B:F,2,FALSE),"Non trouvé") -> Kinshasa | H10: =IFERROR(VLOOKUP(C10,'Registre maintenance'!B:F,3,FALSE),"Non trouvé") -> -5.412628 | I10: =IFERROR(VLOOKUP(C10,'Registre maintenance'!B:F,4,FALSE),"Non trouvé") -> 25.498236 | J10: =IFERROR(VLOOKUP(C10,'Registre maintenance'!B:F,5,FALSE),"Non trouvé") -> 5G | K10: =IF(F10=G10,"OK","Mismatch") -> OK
A11: Logs_Reseau_Part_01.xlsx | B11: 45217.109 | C11: ANT-0897 | D11: 59 | E11: Résolu | F11: =F10 -> Kinshasa | G11: =IFERROR(VLOOKUP(C11,'Registre maintenance'!B:F,2,FALSE),"Non trouvé") -> Non trouvé | H11: =IFERROR(VLOOKUP(C11,'Registre maintenance'!B:F,3,FALSE),"Non trouvé") -> Non trouvé | I11: =IFERROR(VLOOKUP(C11,'Registre maintenance'!B:F,4,FALSE),"Non trouvé") -> Non trouvé | J11: =IFERROR(VLOOKUP(C11,'Registre maintenance'!B:F,5,FALSE),"Non trouvé") -> Non trouvé | K11: =IF(F11=G11,"OK","Mismatch") -> Mismatch
A12: Logs_Reseau_Part_01.xlsx | B12: 45213.042 | C12: ANT-0737 | D12: 119 | E12: Non Résolu | F12: Kongo-Central | G12: =IFERROR(VLOOKUP(C12,'Registre maintenance'!B:F,2,FALSE),"Non trouvé") -> Kongo-Central | H12: =IFERROR(VLOOKUP(C12,'Registre maintenance'!B:F,3,FALSE),"Non trouvé") -> -2.821152 | I12: =IFERROR(VLOOKUP(C12,'Registre maintenance'!B:F,4,FALSE),"Non trouvé") -> 20.651419 | J12: =IFERROR(VLOOKUP(C12,'Registre maintenance'!B:F,5,FALSE),"Non trouvé") -> 5G | K12: =IF(F12=G12,"OK","Mismatch") -> OK
A13: Logs_Reseau_Part_03.xlsx | B13: 45213.023 | C13: ANT-0737 | D13: 56 | E13: En Cours | F13: Kongo-Central | G13: =IFERROR(VLOOKUP(C13,'Registre maintenance'!B:F,2,FALSE),"Non trouvé") -> Kongo-Central | H13: =IFERROR(VLOOKUP(C13,'Registre maintenance'!B:F,3,FALSE),"Non trouvé") -> -2.821152 | I13: =IFERROR(VLOOKUP(C13,'Registre maintenance'!B:F,4,FALSE),"Non trouvé") -> 20.651419 | J13: =IFERROR(VLOOKUP(C13,'Registre maintenance'!B:F,5,FALSE),"Non trouvé") -> 5G | K13: =IF(F13=G13,"OK","Mismatch") -> OK
A14: Logs_Reseau_Part_01.xlsx | B14: 45202.26 | C14: ANT-0270 | D14: 79 | E14: Résolu | F14: Kasai-Central | G14: =IFERROR(VLOOKUP(C14,'Registre maintenance'!B:F,2,FALSE),"Non trouvé") -> Kasai-Central | H14: =IFERROR(VLOOKUP(C14,'Registre maintenance'!B:F,3,FALSE),"Non trouvé") -> -1.648264 | I14: =IFERROR(VLOOKUP(C14,'Registre maintenance'!B:F,4,FALSE),"Non trouvé") -> 28.866144 | J14: =IFERROR(VLOOKUP(C14,'Registre maintenance'!B:F,5,FALSE),"Non trouvé") -> 5G | K14: =IF(F14=G14,"OK","Mismatch") -> OK
A15: Logs_Reseau_Part_01.xlsx | B15: 45216.792 | C15: ANT-0996 | D15: 56 | E15: Résolu | F15: =F14 -> Kasai-Central | G15: =IFERROR(VLOOKUP(C15,'Registre maintenance'!B:F,2,FALSE),"Non trouvé") -> Non trouvé | H15: =IFERROR(VLOOKUP(C15,'Registre maintenance'!B:F,3,FALSE),"Non trouvé") -> Non trouvé | I15: =IFERROR(VLOOKUP(C15,'Registre maintenance'!B:F,4,FALSE),"Non trouvé") -> Non trouvé | J15: =IFERROR(VLOOKUP(C15,'Registre maintenance'!B:F,5,FALSE),"Non trouvé") -> Non trouvé | K15: =IF(F15=G15,"OK","Mismatch") -> Mismatch
A16: Logs_Reseau_Part_03.xlsx | B16: 45216.903 | C16: ANT-0642 | D16: 20 | E16: En Cours | F16: Kwilu | G16: =IFERROR(VLOOKUP(C16,'Registre maintenance'!B:F,2,FALSE),"Non trouvé") -> Kwilu | H16: =IFERROR(VLOOKUP(C16,'Registre maintenance'!B:F,3,FALSE),"Non trouvé") -> -4.240836 | I16: =IFERROR(VLOOKUP(C16,'Registre maintenance'!B:F,4,FALSE),"Non trouvé") -> 26.210014 | J16: =IFERROR(VLOOKUP(C16,'Registre maintenance'!B:F,5,FALSE),"Non trouvé") -> 4G | K16: =IF(F16=G16,"OK","Mismatch") -> OK
A17: Logs_Reseau_Part_08.xlsx | B17: 45221.376 | C17: ANT-0079 | D17: 59 | E17: En Cours | F17: Maniema | G17: =IFERROR(VLOOKUP(C17,'Registre maintenance'!B:F,2,FALSE),"Non trouvé") -> Maniema | H17: =IFERROR(VLOOKUP(C17,'Registre maintenance'!B:F,3,FALSE),"Non trouvé") -> -8.482467 | I17: =IFERROR(VLOOKUP(C17,'Registre maintenance'!B:F,4,FALSE),"Non trouvé") -> 21.897778 | J17: =IFERROR(VLOOKUP(C17,'Registre maintenance'!B:F,5,FALSE),"Non trouvé") -> 5G | K17: =IF(F17=G17,"OK","Mismatch") -> OK
A18: Logs_Reseau_Part_01.xlsx | B18: 45217.281 | C18: ANT-0513 | D18: 51 | E18: Non Résolu | F18: =F17 -> Maniema | G18: =IFERROR(VLOOKUP(C18,'Registre maintenance'!B:F,2,FALSE),"Non trouvé") -> Non trouvé | H18: =IFERROR(VLOOKUP(C18,'Registre maintenance'!B:F,3,FALSE),"Non trouvé") -> Non trouvé | I18: =IFERROR(VLOOKUP(C18,'Registre maintenance'!B:F,4,FALSE),"Non trouvé") -> Non trouvé | J18: =IFERROR(VLOOKUP(C18,'Registre maintenance'!B:F,5,FALSE),"Non trouvé") -> Non trouvé | K18: =IF(F18=G18,"OK","Mismatch") -> Mismatch
A19: Logs_Reseau_Part_02.xlsx | B19: 45216.674 | C19: ANT-0078 | D19: 117 | E19: Résolu | F19: Sud-Ubangi | G19: =IFERROR(VLOOKUP(C19,'Registre maintenance'!B:F,2,FALSE),"Non trouvé") -> Sud-Ubangi | H19: =IFERROR(VLOOKUP(C19,'Registre maintenance'!B:F,3,FALSE),"Non trouvé") -> -12.141233 | I19: =IFERROR(VLOOKUP(C19,'Registre maintenance'!B:F,4,FALSE),"Non trouvé") -> 15.179044 | J19: =IFERROR(VLOOKUP(C19,'Registre maintenance'!B:F,5,FALSE),"Non trouvé") -> 5G | K19: =IF(F19=G19,"OK","Mismatch") -> OK
A20: Logs_Reseau_Part_01.xlsx | B20: 45220.94 | C20: ANT-0781 | D20: 33 | E20: En Cours | F20: =F19 -> Sud-Ubangi | G20: =IFERROR(VLOOKUP(C20,'Registre maintenance'!B:F,2,FALSE),"Non trouvé") -> Non trouvé | H20: =IFERROR(VLOOKUP(C20,'Registre maintenance'!B:F,3,FALSE),"Non trouvé") -> Non trouvé | I20: =IFERROR(VLOOKUP(C20,'Registre maintenance'!B:F,4,FALSE),"Non trouvé") -> Non trouvé | J20: =IFERROR(VLOOKUP(C20,'Registre maintenance'!B:F,5,FALSE),"Non trouvé") -> Non trouvé | K20: =IF(F20=G20,"OK","Mismatch") -> Mismatch
A21: Logs_Reseau_Part_01.xlsx | B21: 45227.483 | C21: ANT-0781 | D21: 81 | E21: Non Résolu | F21: =F20 -> Sud-Ubangi | G21: =IFERROR(VLOOKUP(C21,'Registre maintenance'!B:F,2,FALSE),"Non trouvé") -> Non trouvé | H21: =IFERROR(VLOOKUP(C21,'Registre maintenance'!B:F,3,FALSE),"Non trouvé") -> Non trouvé | I21: =IFERROR(VLOOKUP(C21,'Registre maintenance'!B:F,4,FALSE),"Non trouvé") -> Non trouvé | J21: =IFERROR(VLOOKUP(C21,'Registre maintenance'!B:F,5,FALSE),"Non trouvé") -> Non trouvé | K21: =IF(F21=G21,"OK","Mismatch") -> Mismatch
A22: Logs_Reseau_Part_03.xlsx | B22: 45229.738 | C22: ANT-0914 | D22: 36 | E22: Non Résolu | F22: Lomami | G22: =IFERROR(VLOOKUP(C22,'Registre maintenance'!B:F,2,FALSE),"Non trouvé") -> Lomami | H22: =IFERROR(VLOOKUP(C22,'Registre maintenance'!B:F,3,FALSE),"Non trouvé") -> -11.218454 | I22: =IFERROR(VLOOKUP(C22,'Registre maintenance'!B:F,4,FALSE),"Non trouvé") -> 28.230025 | J22: =IFERROR(VLOOKUP(C22,'Registre maintenance'!B:F,5,FALSE),"Non trouvé") -> 5G | K22: =IF(F22=G22,"OK","Mismatch") -> OK
A23: Logs_Reseau_Part_01.xlsx | B23: 45217.969 | C23: ANT-0020 | D23: 97 | E23: Non Résolu | F23: Kasai | G23: =IFERROR(VLOOKUP(C23,'Registre maintenance'!B:F,2,FALSE),"Non trouvé") -> Kasai | H23: =IFERROR(VLOOKUP(C23,'Registre maintenance'!B:F,3,FALSE),"Non trouvé") -> -10.059846 | I23: =IFERROR(VLOOKUP(C23,'Registre maintenance'!B:F,4,FALSE),"Non trouvé") -> 14.375758 | J23: =IFERROR(VLOOKUP(C23,'Registre maintenance'!B:F,5,FALSE),"Non trouvé") -> 4G | K23: =IF(F23=G23,"OK","Mismatch") -> OK
A24: Logs_Reseau_Part_01.xlsx | B24: 45213.311 | C24: ANT-0183 | D24: 22 | E24: Non Résolu | F24: =F23 -> Kasai | G24: =IFERROR(VLOOKUP(C24,'Registre maintenance'!B:F,2,FALSE),"Non trouvé") -> Non trouvé | H24: =IFERROR(VLOOKUP(C24,'Registre maintenance'!B:F,3,FALSE),"Non trouvé") -> Non trouvé | I24: =IFERROR(VLOOKUP(C24,'Registre maintenance'!B:F,4,FALSE),"Non trouvé") -> Non trouvé | J24: =IFERROR(VLOOKUP(C24,'Registre maintenance'!B:F,5,FALSE),"Non trouvé") -> Non trouvé | K24: =IF(F24=G24,"OK","Mismatch") -> Mismatch
A25: Logs_Reseau_Part_01.xlsx | B25: 45218.369 | C25: ANT-0520 | D25: 70 | E25: Résolu | F25: Lomami | G25: =IFERROR(VLOOKUP(C25,'Registre maintenance'!B:F,2,FALSE),"Non trouvé") -> Lomami | H25: =IFERROR(VLOOKUP(C25,'Registre maintenance'!B:F,3,FALSE),"Non trouvé") -> -8.422786 | I25: =IFERROR(VLOOKUP(C25,'Registre maintenance'!B:F,4,FALSE),"Non trouvé") -> 16.781293 | J25: =IFERROR(VLOOKUP(C25,'Registre maintenance'!B:F,5,FALSE),"Non trouvé") -> 4G | K25: =IF(F25=G25,"OK","Mismatch") -> OK
A26: Logs_Reseau_Part_01.xlsx | B26: 45208.074 | C26: ANT-0520 | D26: 85 | E26: Non Résolu | F26: Lomami | G26: =IFERROR(VLOOKUP(C26,'Registre maintenance'!B:F,2,FALSE),"Non trouvé") -> Lomami | H26: =IFERROR(VLOOKUP(C26,'Registre maintenance'!B:F,3,FALSE),"Non trouvé") -> -8.422786 | I26: =IFERROR(VLOOKUP(C26,'Registre maintenance'!B:F,4,FALSE),"Non trouvé") -> 16.781293 | J26: =IFERROR(VLOOKUP(C26,'Registre maintenance'!B:F,5,FALSE),"Non trouvé") -> 4G | K26: =IF(F26=G26,"OK","Mismatch") -> OK
A27: Logs_Reseau_Part_04.xlsx | B27: 45209.901 | C27: ANT-0596 | D27: 68 | E27: Non Résolu | F27: Sud-Ubangi | G27: =IFERROR(VLOOKUP(C27,'Registre maintenance'!B:F,2,FALSE),"Non trouvé") -> Sud-Ubangi | H27: =IFERROR(VLOOKUP(C27,'Registre maintenance'!B:F,3,FALSE),"Non trouvé") -> -8.324156 | I27: =IFERROR(VLOOKUP(C27,'Registre maintenance'!B:F,4,FALSE),"Non trouvé") -> 19.543866 | J27: =IFERROR(VLOOKUP(C27,'Registre maintenance'!B:F,5,FALSE),"Non trouvé") -> 4G | K27: =IF(F27=G27,"OK","Mismatch") -> OK
A28: Logs_Reseau_Part_01.xlsx | B28: 45227.033 | C28: ANT-0935 | D28: 68 | E28: En Cours | F28: Nord-Ubangi | G28: =IFERROR(VLOOKUP(C28,'Registre maintenance'!B:F,2,FALSE),"Non trouvé") -> Nord-Ubangi | H28: =IFERROR(VLOOKUP(C28,'Registre maintenance'!B:F,3,FALSE),"Non trouvé") -> -10.375267 | I28: =IFERROR(VLOOKUP(C28,'Registre maintenance'!B:F,4,FALSE),"Non trouvé") -> 17.993663 | J28: =IFERROR(VLOOKUP(C28,'Registre maintenance'!B:F,5,FALSE),"Non trouvé") -> 5G | K28: =IF(F28=G28,"OK","Mismatch") -> OK
A29: Logs_Reseau_Part_01.xlsx | B29: 45225.239 | C29: ANT-0109 | D29: 16 | E29: Non Résolu | F29: =F28 -> Nord-Ubangi | G29: =IFERROR(VLOOKUP(C29,'Registre maintenance'!B:F,2,FALSE),"Non trouvé") -> Non trouvé | H29: =IFERROR(VLOOKUP(C29,'Registre maintenance'!B:F,3,FALSE),"Non trouvé") -> Non trouvé | I29: =IFERROR(VLOOKUP(C29,'Registre maintenance'!B:F,4,FALSE),"Non trouvé") -> Non trouvé | J29: =IFERROR(VLOOKUP(C29,'Registre maintenance'!B:F,5,FALSE),"Non trouvé") -> Non trouvé | K29: =IF(F29=G29,"OK","Mismatch") -> Mismatch
A30: Logs_Reseau_Part_01.xlsx | B30: 45225.239 | C30: ANT-0109 | D30: 16 | E30: Non Résolu | F30: =F29 -> Nord-Ubangi | G30: =IFERROR(VLOOKUP(C30,'Registre maintenance'!B:F,2,FALSE),"Non trouvé") -> Non trouvé | H30: =IFERROR(VLOOKUP(C30,'Registre maintenance'!B:F,3,FALSE),"Non trouvé") -> Non trouvé | I30: =IFERROR(VLOOKUP(C30,'Registre maintenance'!B:F,4,FALSE),"Non trouvé") -> Non trouvé | J30: =IFERROR(VLOOKUP(C30,'Registre maintenance'!B:F,5,FALSE),"Non trouvé") -> Non trouvé | K30: =IF(F30=G30,"OK","Mismatch") -> Mismatch
A31: Logs_Reseau_Part_08.xlsx | B31: 45200.116 | C31: ANT-0109 | D31: 111 | E31: En Cours | F31: =F30 -> Nord-Ubangi | G31: =IFERROR(VLOOKUP(C31,'Registre maintenance'!B:F,2,FALSE),"Non trouvé") -> Non trouvé | H31: =IFERROR(VLOOKUP(C31,'Registre maintenance'!B:F,3,FALSE),"Non trouvé") -> Non trouvé | I31: =IFERROR(VLOOKUP(C31,'Registre maintenance'!B:F,4,FALSE),"Non trouvé") -> Non trouvé | J31: =IFERROR(VLOOKUP(C31,'Registre maintenance'!B:F,5,FALSE),"Non trouvé") -> Non trouvé | K31: =IF(F31=G31,"OK","Mismatch") -> Mismatch
A32: Logs_Reseau_Part_04.xlsx | B32: 45221.517 | C32: ANT-0415 | D32: 83 | E32: En Cours | F32: Sud-Kivu | G32: =IFERROR(VLOOKUP(C32,'Registre maintenance'!B:F,2,FALSE),"Non trouvé") -> Sud-Kivu | H32: =IFERROR(VLOOKUP(C32,'Registre maintenance'!B:F,3,FALSE),"Non trouvé") -> -2.965153 | I32: =IFERROR(VLOOKUP(C32,'Registre maintenance'!B:F,4,FALSE),"Non trouvé") -> 29.79908 | J32: =IFERROR(VLOOKUP(C32,'Registre maintenance'!B:F,5,FALSE),"Non trouvé") -> 4G | K32: =IF(F32=G32,"OK","Mismatch") -> OK
A33: Logs_Reseau_Part_08.xlsx | B33: 45218.676 | C33: ANT-0415 | D33: 37 | E33: En Cours | F33: Sud-Kivu | G33: =IFERROR(VLOOKUP(C33,'Registre maintenance'!B:F,2,FALSE),"Non trouvé") -> Sud-Kivu | H33: =IFERROR(VLOOKUP(C33,'Registre maintenance'!B:F,3,FALSE),"Non trouvé") -> -2.965153 | I33: =IFERROR(VLOOKUP(C33,'Registre maintenance'!B:F,4,FALSE),"Non trouvé") -> 29.79908 | J33: =IFERROR(VLOOKUP(C33,'Registre maintenance'!B:F,5,FALSE),"Non trouvé") -> 4G | K33: =IF(F33=G33,"OK","Mismatch") -> OK
A34: Logs_Reseau_Part_09.xlsx | B34: 45205.052 | C34: ANT-0788 | D34: 81 | E34: En Cours | F34: Kasai | G34: =IFERROR(VLOOKUP(C34,'Registre maintenance'!B:F,2,FALSE),"Non trouvé") -> Kasai | H34: =IFERROR(VLOOKUP(C34,'Registre maintenance'!B:F,3,FALSE),"Non trouvé") -> 1.580286 | I34: =IFERROR(VLOOKUP(C34,'Registre maintenance'!B:F,4,FALSE),"Non trouvé") -> 20.99053 | J34: =IFERROR(VLOOKUP(C34,'Registre maintenance'!B:F,5,FALSE),"Non trouvé") -> 4G | K34: =IF(F34=G34,"OK","Mismatch") -> OK
A35: Logs_Reseau_Part_01.xlsx | B35: 45213.428 | C35: ANT-0892 | D35: 101 | E35: Non Résolu | F35: =F34 -> Kasai | G35: =IFERROR(VLOOKUP(C35,'Registre maintenance'!B:F,2,FALSE),"Non trouvé") -> Non trouvé | H35: =IFERROR(VLOOKUP(C35,'Registre maintenance'!B:F,3,FALSE),"Non trouvé") -> Non trouvé | I35: =IFERROR(VLOOKUP(C35,'Registre maintenance'!B:F,4,FALSE),"Non trouvé") -> Non trouvé | J35: =IFERROR(VLOOKUP(C35,'Registre maintenance'!B:F,5,FALSE),"Non trouvé") -> Non trouvé | K35: =IF(F35=G35,"OK","Mismatch") -> Mismatch
A36: Logs_Reseau_Part_08.xlsx | C36: ANT-0892 | D36: 10 | E36: Non Résolu | F36: =F35 -> Kasai | G36: =IFERROR(VLOOKUP(C36,'Registre maintenance'!B:F,2,FALSE),"Non trouvé") -> Non trouvé | H36: =IFERROR(VLOOKUP(C36,'Registre maintenance'!B:F,3,FALSE),"Non trouvé") -> Non trouvé | I36: =IFERROR(VLOOKUP(C36,'Registre maintenance'!B:F,4,FALSE),"Non trouvé") -> Non trouvé | J36: =IFERROR(VLOOKUP(C36,'Registre maintenance'!B:F,5,FALSE),"Non trouvé") -> Non trouvé | K36: =IF(F36=G36,"OK","Mismatch") -> Mismatch
A37: Logs_Reseau_Part_03.xlsx | B37: 45229.444 | C37: ANT-0929 | D37: 5 | E37: Résolu | F37: Kasai-Central | G37: =IFERROR(VLOOKUP(C37,'Registre maintenance'!B:F,2,FALSE),"Non trouvé") -> Kasai-Central | H37: =IFERROR(VLOOKUP(C37,'Registre maintenance'!B:F,3,FALSE),"Non trouvé") -> -6.680371 | I37: =IFERROR(VLOOKUP(C37,'Registre maintenance'!B:F,4,FALSE),"Non trouvé") -> 21.955673 | J37: =IFERROR(VLOOKUP(C37,'Registre maintenance'!B:F,5,FALSE),"Non trouvé") -> 4G | K37: =IF(F37=G37,"OK","Mismatch") -> OK
A38: Logs_Reseau_Part_02.xlsx | B38: 45222.631 | C38: ANT-0565 | D38: 90 | E38: Résolu | F38: Tanganyika | G38: =IFERROR(VLOOKUP(C38,'Registre maintenance'!B:F,2,FALSE),"Non trouvé") -> Tanganyika | H38: =IFERROR(VLOOKUP(C38,'Registre maintenance'!B:F,3,FALSE),"Non trouvé") -> -2.099631 | I38: =IFERROR(VLOOKUP(C38,'Registre maintenance'!B:F,4,FALSE),"Non trouvé") -> 13.97464 | J38: =IFERROR(VLOOKUP(C38,'Registre maintenance'!B:F,5,FALSE),"Non trouvé") -> 3G | K38: =IF(F38=G38,"OK","Mismatch") -> OK
A39: Logs_Reseau_Part_01.xlsx | B39: 45204.283 | C39: ANT-0641 | D39: 11 | E39: En Cours | F39: =F38 -> Tanganyika | G39: =IFERROR(VLOOKUP(C39,'Registre maintenance'!B:F,2,FALSE),"Non trouvé") -> Non trouvé | H39: =IFERROR(VLOOKUP(C39,'Registre maintenance'!B:F,3,FALSE),"Non trouvé") -> Non trouvé | I39: =IFERROR(VLOOKUP(C39,'Registre maintenance'!B:F,4,FALSE),"Non trouvé") -> Non trouvé | J39: =IFERROR(VLOOKUP(C39,'Registre maintenance'!B:F,5,FALSE),"Non trouvé") -> Non trouvé | K39: =IF(F39=G39,"OK","Mismatch") -> Mismatch
A40: Logs_Reseau_Part_05.xlsx | B40: 45215.376 | C40: ANT-0641 | D40: 65 | E40: En Cours | F40: =F39 -> Tanganyika | G40: =IFERROR(VLOOKUP(C40,'Registre maintenance'!B:F,2,FALSE),"Non trouvé") -> Non trouvé | H40: =IFERROR(VLOOKUP(C40,'Registre maintenance'!B:F,3,FALSE),"Non trouvé") -> Non trouvé | I40: =IFERROR(VLOOKUP(C40,'Registre maintenance'!B:F,4,FALSE),"Non trouvé") -> Non trouvé | J40: =IFERROR(VLOOKUP(C40,'Registre maintenance'!B:F,5,FALSE),"Non trouvé") -> Non trouvé | K40: =IF(F40=G40,"OK","Mismatch") -> Mismatch
...

Sheet Registre maintenance
A1: Source.Name | B1: ID_Antenne | C1: Province_RDC | D1: Latitude | E1: Longitude | F1: Technologie | G1: Equipementier
A2: Registre_Maintenance_Part_01.xlsx | B2: ANT-0622 | C2: Haut-Uele | D2: -3.003879 | E2: 23.633893 | F2: 5G | G2: Ericsson
A3: Registre_Maintenance_Part_01.xlsx | B3: ANT-0084 | C3: Kwilu | D3: 2.413557 | E3: 19.690682 | F3: 4G | G3: Huawei
A4: Registre_Maintenance_Part_01.xlsx | B4: ANT-0862 | C4: Tanganyika | D4: -9.470862 | E4: 29.234388 | F4: 3G | G4: ZTE
A5: Registre_Maintenance_Part_01.xlsx | B5: ANT-0288 | C5: Tshopo | D5: 1.400674 | E5: 13.503127 | F5: 5G | G5: ZTE
A6: Registre_Maintenance_Part_01.xlsx | B6: ANT-0880 | C6: Haut-Uele | D6: 0.293756 | E6: 18.528884 | F6: 5G | G6: ZTE
A7: Registre_Maintenance_Part_01.xlsx | B7: ANT-0847 | C7: Maniema | D7: -4.486234 | E7: 17.956159 | F7: 3G | G7: Huawei
A8: Registre_Maintenance_Part_01.xlsx | B8: ANT-0144 | C8: Tanganyika | D8: -12.824639 | E8: 24.407249 | F8: 5G | G8: Huawei
A9: Registre_Maintenance_Part_01.xlsx | B9: ANT-0913 | C9: Kinshasa | D9: -5.412628 | E9: 25.498236 | F9: 5G | G9: ZTE
A10: Registre_Maintenance_Part_01.xlsx | B10: ANT-0552 | C10: Kinshasa | D10: -10.57951 | E10: 23.502314 | F10: 4G | G10: ZTE
A11: Registre_Maintenance_Part_01.xlsx | B11: ANT-0202 | C11: Tshuapa | D11: 3.078867 | E11: 19.513651 | F11: 5G | G11: Huawei
A12: Registre_Maintenance_Part_01.xlsx | B12: ANT-0270 | C12: Kasai-Central | D12: -1.648264 | E12: 28.866144 | F12: 5G | G12: Ericsson
A13: Registre_Maintenance_Part_01.xlsx | B13: ANT-0752 | C13: Nord-Kivu | D13: -3.388313 | E13: 26.838507 | F13: 5G | G13: Nokia
... A243: Registre_Maintenance_Part_05.xlsx | B243: ANT-0630 | C243: Kwango | D243: -8.121062 | E243: 21.09439 | F243: 5G | G243: ZTE
A244: Registre_Maintenance_Part_05.xlsx | B244: ANT-0615 | D244: 3.979001 | E244: 28.069559 | F244: 3G | G244: Huawei
A245: Registre_Maintenance_Part_05.xlsx | B245: ANT-0040 | C245: Tshopo | D245: 1.472051 | E245: 17.36289 | F245: 4G | G245: Huawei
A246: Registre_Maintenance_Part_05.xlsx | B246: ANT-0545 | C246: Kinshasa | D246: -2.666507 | E246: 18.623693 | F246: 3G | G246: ZTE
A247: Registre_Maintenance_Part_05.xlsx | B247: ANT-0516 | C247: Haut-Katanga | D247: -9.91705 | E247: 22.918887 | F247: 4G | G247: Huawei
A248: Registre_Maintenance_Part_05.xlsx | B248: ANT-0121 | C248: Bas-Uele | D248: -7.395204 | E248: 21.651044 | F248: 4G | G248: Huawei
A249: Registre_Maintenance_Part_05.xlsx | B249: ANT-0096 | C249: Tshopo | D249: 3.060376 | E249: 19.708034 | F249: 3G | G249: ZTE
A250: Registre_Maintenance_Part_05.xlsx | B250: ANT-0796 | C250: Mai-Ndombe | D250: -3.269612 | E250: 25.571189 | F250: 5G | G250: Ericsson
A251: Registre_Maintenance_Part_05.xlsx | B251: ANT-0789 | C251: Kasai-Central | D251: -12.086929 | E251: 14.032645 | F251: 3G | G251: ZTE
A252: Registre_Maintenance_Part_06.xlsx | B252: ANT-0134 | C252: Kwango | D252: -10.963041 | E252: 12.269857 | F252: 4G | G252: Huawei
A253: Registre_Maintenance_Part_06.xlsx | B253: ANT-0618 | C253: Mongala | D253: -4.332408 | E253: 14.119439 | F253: 5G | G253: Nokia
A254: Registre_Maintenance_Part_06.xlsx | B254: ANT-0964 | C254: Kinshasa | D254: -0.571049 | E254: 15.317663 | F254: 5G | G254: Nokia
A255: Registre_Maintenance_Part_06.xlsx | B255: ANT-0002 | C255: Mai-Ndombe | D255: -10.442425 | E255: 23.243632 | F255: 4G | G255: Nokia
A256: Registre_Maintenance_Part_06.xlsx | B256: ANT-0695 | C256: Haut-Lomami | D256: 0.163277 | E256: 14.871577 | F256: 4G | G256: Huawei
... A401: Registre_Maintenance_Part_08.xlsx | B401: ANT-0357 | C401: Tanganyika | D401: -11.793894 | E401: 20.433341 | F401: 5G | G401: Nokia
